<?xml version="1.0"?>
<robot name="mycobot280_pi_gripper">

  <!-- Fix the base to world -->
  <link name="world"/>
  <joint name="world_to_base" type="fixed">
    <parent link="world"/>
    <child link="g_base"/>
    <origin xyz="0 0 0" rpy="0 0 0"/>
  </joint>

  <!-- ===== Base link ===== -->
  <link name="g_base">
    <visual>
      <geometry>
        <mesh filename="package://mycobot280_pi/urdf/meshes/G_base.dae"/>
      </geometry>
      <origin xyz="0 0 -0.03" rpy="0 0 1.5708"/>
    </visual>
    <collision>
      <geometry>
        <box size="0.08 0.08 0.04"/>
      </geometry>
      <origin xyz="0 0 -0.03" rpy="0 0 1.5708"/>
    </collision>
    <inertial>
      <mass value="0.33"/>
      <inertia ixx="0.000784" ixy="0" ixz="0" iyy="0.000867" iyz="0" izz="0.001598"/>
      <origin xyz="0 0 0" rpy="0 0 0"/>
    </inertial>
  </link>

  <!-- ===== Joint 1 ===== -->
  <link name="joint1">
    <visual>
      <geometry>
        <mesh filename="package://mycobot280_pi/urdf/meshes/joint1.stl"/>
      </geometry>
      <origin xyz="0 0 0" rpy="1.5708 0 0"/>
    </visual>
    <collision>
      <geometry>
        <box size="0.06 0.06 0.06"/>
      </geometry>
      <origin xyz="0 0 0" rpy="0 0 0"/>
    </collision>
    <inertial>
      <mass value="0.12"/>
      <inertia ixx="0.000074" ixy="0" ixz="0" iyy="0.000086" iyz="0" izz="0.000137"/>
      <origin xyz="0 0 0" rpy="0 0 0"/>
    </inertial>
  </link>

  <!-- ===== Joint 2 ===== -->
  <link name="joint2">
    <visual>
      <geometry>
        <mesh filename="package://mycobot280_pi/urdf/meshes/joint2.dae"/>
      </geometry>
      <origin xyz="0 0 -0.06096" rpy="0 0 -1.5708"/>
    </visual>
    <collision>
      <geometry>
        <box size="0.05 0.05 0.08"/>
      </geometry>
      <origin xyz="0 0 -0.06096" rpy="0 0 0"/>
    </collision>
    <inertial>
      <mass value="0.19"/>
      <inertia ixx="0.000098" ixy="0" ixz="0" iyy="0.000113" iyz="0" izz="0.000185"/>
      <origin xyz="0 0 0" rpy="0 0 0"/>
    </inertial>
  </link>

  <!-- ===== Joint 3 ===== -->
  <link name="joint3">
    <visual>
      <geometry>
        <mesh filename="package://mycobot280_pi/urdf/meshes/joint3.dae"/>
      </geometry>
      <origin xyz="0 0 0.03256" rpy="0 -1.5708 0"/>
    </visual>
    <collision>
      <geometry>
        <box size="0.05 0.05 0.06"/>
      </geometry>
      <origin xyz="0 0 0.03" rpy="0 0 0"/>
    </collision>
    <inertial>
      <mass value="0.09"/>
      <inertia ixx="0.000035" ixy="0" ixz="0" iyy="0.000042" iyz="0" izz="0.000065"/>
      <origin xyz="0 0 0" rpy="0 0 0"/>
    </inertial>
  </link>

  <!-- ===== Joint 4 ===== -->
  <link name="joint4">
    <visual>
      <geometry>
        <mesh filename="package://mycobot280_pi/urdf/meshes/joint4.dae"/>
      </geometry>
      <origin xyz="0 0 0.03056" rpy="0 -1.5708 0"/>
    </visual>
    <collision>
      <geometry>
        <box size="0.05 0.05 0.05"/>
      </geometry>
      <origin xyz="0 0 0.03" rpy="0 0 0"/>
    </collision>
    <inertial>
      <mass value="0.08"/>
      <inertia ixx="0.000022" ixy="0" ixz="0" iyy="0.000026" iyz="0" izz="0.000040"/>
      <origin xyz="0 0 0" rpy="0 0 0"/>
    </inertial>
  </link>

  <!-- ===== Joint 5 ===== -->
  <link name="joint5">
    <visual>
      <geometry>
        <mesh filename="package://mycobot280_pi/urdf/meshes/joint5.stl"/>
      </geometry>
      <origin xyz="0 -0.001 -0.0345" rpy="0 -1.5708 3.1416"/>
    </visual>
    <collision>
      <geometry>
        <box size="0.04 0.04 0.04"/>
      </geometry>
      <origin xyz="0 0 -0.03" rpy="0 0 0"/>
    </collision>
    <inertial>
      <mass value="0.06"/>
      <inertia ixx="0.000015" ixy="0" ixz="0" iyy="0.000018" iyz="0" izz="0.000027"/>
      <origin xyz="0 0 0" rpy="0 0 0"/>
    </inertial>
  </link>

  <!-- ===== Joint 6 ===== -->
  <link name="joint6">
    <visual>
      <geometry>
        <mesh filename="package://mycobot280_pi/urdf/meshes/joint6.dae"/>
      </geometry>
      <origin xyz="0 0 -0.038" rpy="0 0 0"/>
    </visual>
    <collision>
      <geometry>
        <box size="0.04 0.04 0.04"/>
      </geometry>
      <origin xyz="0 0 -0.03" rpy="0 0 0"/>
    </collision>
    <inertial>
      <mass value="0.045"/>
      <inertia ixx="0.000010" ixy="0" ixz="0" iyy="0.000011" iyz="0" izz="0.000017"/>
      <origin xyz="0 0 0" rpy="0 0 0"/>
    </inertial>
  </link>

  <!-- ===== Flange ===== -->
  <link name="joint6_flange">
    <visual>
      <geometry>
        <mesh filename="package://mycobot280_pi/urdf/meshes/joint7.dae"/>
      </geometry>
      <origin xyz="0 0 -0.012" rpy="0 0 0"/>
    </visual>
    <collision>
      <geometry>
        <box size="0.03 0.03 0.03"/>
      </geometry>
      <origin xyz="0 0 -0.012" rpy="0 0 0"/>
    </collision>
    <inertial>
      <mass value="0.025"/>
      <inertia ixx="0.000006" ixy="0" ixz="0" iyy="0.000007" iyz="0" izz="0.000011"/>
      <origin xyz="0 0 0" rpy="0 0 0"/>
    </inertial>
  </link>

  <!-- ===== 机械臂关节（完全保留原文件） ===== -->
  <joint name="g_base_to_joint1" type="fixed">
    <parent link="g_base"/>
    <child link="joint1"/>
    <origin xyz="0 0 0" rpy="0 0 0"/>
  </joint>

  <joint name="joint2_to_joint1" type="revolute">
    <parent link="joint1"/>
    <child link="joint2"/>
    <origin xyz="0 0 0.13956" rpy="0 0 0"/>
    <axis xyz="0 0 1"/>
    <limit lower="-2.9322" upper="2.9322" effort="5.0" velocity="2.0"/>
    <dynamics damping="0.05" friction="0.01"/>
  </joint>

  <joint name="joint3_to_joint2" type="revolute">
    <parent link="joint2"/>
    <child link="joint3"/>
    <origin xyz="0 0 -0.001" rpy="0 1.5708 -1.5708"/>
    <axis xyz="0 0 1"/>
    <limit lower="-2.3562" upper="2.3562" effort="5.0" velocity="2.0"/>
    <dynamics damping="0.05" friction="0.01"/>
  </joint>

  <joint name="joint4_to_joint3" type="revolute">
    <parent link="joint3"/>
    <child link="joint4"/>
    <origin xyz="-0.1104 0 0" rpy="0 0 0"/>
    <axis xyz="0 0 1"/>
    <limit lower="-2.618" upper="2.618" effort="5.0" velocity="2.0"/>
    <dynamics damping="0.05" friction="0.01"/>
  </joint>

  <joint name="joint5_to_joint4" type="revolute">
    <parent link="joint4"/>
    <child link="joint5"/>
    <origin xyz="-0.096 0 0.06462" rpy="0 0 -1.5708"/>
    <axis xyz="0 0 1"/>
    <limit lower="-2.5307" upper="2.5307" effort="5.0" velocity="2.0"/>
    <dynamics damping="0.05" friction="0.01"/>
  </joint>

  <joint name="joint6_to_joint5" type="revolute">
    <parent link="joint5"/>
    <child link="joint6"/>
    <origin xyz="0 -0.07318 -0.001" rpy="1.5708 -1.5708 0"/>
    <axis xyz="0 0 1"/>
    <limit lower="-2.8798" upper="2.8798" effort="5.0" velocity="2.0"/>
    <dynamics damping="0.05" friction="0.01"/>
  </joint>

  <joint name="joint6output_to_joint6" type="revolute">
    <parent link="joint6"/>
    <child link="joint6_flange"/>
    <origin xyz="0 0.0456 0" rpy="-1.5708 0 0"/>
    <axis xyz="0 0 1"/>
    <limit lower="-3.14159" upper="3.14159" effort="5.0" velocity="2.0"/>
    <dynamics damping="0.05" friction="0.01"/>
  </joint>

  <!-- ================================================================
       以下为追加的自适应夹爪部分
       links/joints 结构和 origin 完全来自官方 URDF
       inertial/collision 为新增（Gazebo 必须）
       mesh 使用 package://mycobot_description/（在launch中替换为绝对路径）
       ================================================================ -->

  <!-- 夹爪基座（固定在 joint6_flange） -->
  <link name="gripper_base">
    <visual>
      <geometry>
        <mesh filename="package://mycobot_description/urdf/adaptive_gripper/gripper_base.dae"/>
      </geometry>
      <origin xyz="0.0 0 -0.012" rpy="0 0 0"/>
    </visual>
    <collision>
      <geometry>
        <box size="0.06 0.06 0.03"/>
      </geometry>
      <origin xyz="0.0 0 -0.012" rpy="0 0 0"/>
    </collision>
    <inertial>
      <mass value="0.08"/>
      <origin xyz="0 0 -0.012" rpy="0 0 0"/>
      <inertia ixx="0.00005" ixy="0" ixz="0"
               iyy="0.00005" iyz="0"
               izz="0.00005"/>
    </inertial>
  </link>

  <!-- 官方固定关节：joint6_flange -> gripper_base -->
  <joint name="joint6output_to_gripper_base" type="fixed">
    <parent link="joint6_flange"/>
    <child link="gripper_base"/>
    <origin xyz="0 0 0.034" rpy="1.579 0 0"/>
  </joint>

  <!-- gripper_left3（主动关节 gripper_controller 的子link） -->
  <link name="gripper_left3">
    <visual>
      <geometry>
        <mesh filename="package://mycobot_description/urdf/adaptive_gripper/gripper_left3.dae"/>
      </geometry>
      <origin xyz="0.012 0.0025 -0.012" rpy="0 0 0"/>
    </visual>
    <collision>
      <geometry>
        <box size="0.02 0.02 0.03"/>
      </geometry>
      <origin xyz="0.012 0.0025 -0.012" rpy="0 0 0"/>
    </collision>
    <inertial>
      <mass value="0.01"/>
      <origin xyz="0.012 0.0025 -0.012" rpy="0 0 0"/>
      <inertia ixx="0.000005" ixy="0" ixz="0"
               iyy="0.000005" iyz="0"
               izz="0.000005"/>
    </inertial>
  </link>

  <!-- 主动关节（唯一被 ros2_control 驱动的夹爪关节） -->
  <joint name="gripper_controller" type="revolute">
    <axis xyz="0 0 1"/>
    <limit effort="1000.0" lower="-0.74" upper="0.15" velocity="2.0"/>
    <parent link="gripper_base"/>
    <child link="gripper_left3"/>
    <origin xyz="-0.012 0.005 0" rpy="0 0 0"/>
    <dynamics damping="0.5" friction="0.1"/>
  </joint>

  <!-- gripper_left2（mimic） -->
  <link name="gripper_left2">
    <visual>
      <geometry>
        <mesh filename="package://mycobot_description/urdf/adaptive_gripper/gripper_left2.dae"/>
      </geometry>
      <origin xyz="0.005 -0.0195 -0.012" rpy="0 0 0"/>
    </visual>
    <collision>
      <geometry>
        <box size="0.02 0.02 0.03"/>
      </geometry>
      <origin xyz="0.005 -0.0195 -0.012" rpy="0 0 0"/>
    </collision>
    <inertial>
      <mass value="0.01"/>
      <origin xyz="0.005 -0.0195 -0.012" rpy="0 0 0"/>
      <inertia ixx="0.000005" ixy="0" ixz="0"
               iyy="0.000005" iyz="0"
               izz="0.000005"/>
    </inertial>
  </link>

  <joint name="gripper_base_to_gripper_left2" type="revolute">
    <axis xyz="0 0 1"/>
    <limit effort="1000.0" lower="-0.8" upper="0.5" velocity="2.0"/>
    <parent link="gripper_base"/>
    <child link="gripper_left2"/>
    <origin xyz="-0.005 0.027 0" rpy="0 0 0"/>
    <mimic joint="gripper_controller" multiplier="1.0" offset="0"/>
    <dynamics damping="0.5" friction="0.1"/>
  </joint>

  <!-- gripper_left1（mimic） -->
  <link name="gripper_left1">
    <visual>
      <geometry>
        <mesh filename="package://mycobot_description/urdf/adaptive_gripper/gripper_left1.dae"/>
      </geometry>
      <origin xyz="0.039 -0.0133 -0.012" rpy="0 0 0"/>
    </visual>
    <collision>
      <geometry>
        <box size="0.02 0.02 0.03"/>
      </geometry>
      <origin xyz="0.039 -0.0133 -0.012" rpy="0 0 0"/>
    </collision>
    <inertial>
      <mass value="0.01"/>
      <origin xyz="0.039 -0.0133 -0.012" rpy="0 0 0"/>
      <inertia ixx="0.000005" ixy="0" ixz="0"
               iyy="0.000005" iyz="0"
               izz="0.000005"/>
    </inertial>
  </link>

  <joint name="gripper_left3_to_gripper_left1" type="revolute">
    <axis xyz="0 0 1"/>
    <limit effort="1000.0" lower="-0.5" upper="0.5" velocity="2.0"/>
    <parent link="gripper_left3"/>
    <child link="gripper_left1"/>
    <origin xyz="-0.027 0.016 0" rpy="0 0 0"/>
    <mimic joint="gripper_controller" multiplier="-1.0" offset="0"/>
    <dynamics damping="0.5" friction="0.1"/>
  </joint>

  <!-- gripper_right3（mimic） -->
  <link name="gripper_right3">
    <visual>
      <geometry>
        <mesh filename="package://mycobot_description/urdf/adaptive_gripper/gripper_right3.dae"/>
      </geometry>
      <origin xyz="-0.012 0.0025 -0.012" rpy="0 0 0"/>
    </visual>
    <collision>
      <geometry>
        <box size="0.02 0.02 0.03"/>
      </geometry>
      <origin xyz="-0.012 0.0025 -0.012" rpy="0 0 0"/>
    </collision>
    <inertial>
      <mass value="0.01"/>
      <origin xyz="-0.012 0.0025 -0.012" rpy="0 0 0"/>
      <inertia ixx="0.000005" ixy="0" ixz="0"
               iyy="0.000005" iyz="0"
               izz="0.000005"/>
    </inertial>
  </link>

  <joint name="gripper_base_to_gripper_right3" type="revolute">
    <axis xyz="0 0 1"/>
    <limit effort="1000.0" lower="-0.15" upper="0.7" velocity="2.0"/>
    <parent link="gripper_base"/>
    <child link="gripper_right3"/>
    <origin xyz="0.012 0.005 0" rpy="0 0 0"/>
    <mimic joint="gripper_controller" multiplier="-1.0" offset="0"/>
    <dynamics damping="0.5" friction="0.1"/>
  </joint>

  <!-- gripper_right2（mimic） -->
  <link name="gripper_right2">
    <visual>
      <geometry>
        <mesh filename="package://mycobot_description/urdf/adaptive_gripper/gripper_right2.dae"/>
      </geometry>
      <origin xyz="-0.005 -0.0195 -0.012" rpy="0 0 0"/>
    </visual>
    <collision>
      <geometry>
        <box size="0.02 0.02 0.03"/>
      </geometry>
      <origin xyz="-0.005 -0.0195 -0.012" rpy="0 0 0"/>
    </collision>
    <inertial>
      <mass value="0.01"/>
      <origin xyz="-0.005 -0.0195 -0.012" rpy="0 0 0"/>
      <inertia ixx="0.000005" ixy="0" ixz="0"
               iyy="0.000005" iyz="0"
               izz="0.000005"/>
    </inertial>
  </link>

  <joint name="gripper_base_to_gripper_right2" type="revolute">
    <axis xyz="0 0 1"/>
    <limit effort="1000.0" lower="-0.5" upper="0.8" velocity="2.0"/>
    <parent link="gripper_base"/>
    <child link="gripper_right2"/>
    <origin xyz="0.005 0.027 0" rpy="0 0 0"/>
    <mimic joint="gripper_controller" multiplier="-1.0" offset="0"/>
    <dynamics damping="0.5" friction="0.1"/>
  </joint>

  <!-- gripper_right1（mimic） -->
  <link name="gripper_right1">
    <visual>
      <geometry>
        <mesh filename="package://mycobot_description/urdf/adaptive_gripper/gripper_right1.dae"/>
      </geometry>
      <origin xyz="-0.039 -0.0133 -0.012" rpy="0 0 0"/>
    </visual>
    <collision>
      <geometry>
        <box size="0.02 0.02 0.03"/>
      </geometry>
      <origin xyz="-0.039 -0.0133 -0.012" rpy="0 0 0"/>
    </collision>
    <inertial>
      <mass value="0.01"/>
      <origin xyz="-0.039 -0.0133 -0.012" rpy="0 0 0"/>
      <inertia ixx="0.000005" ixy="0" ixz="0"
               iyy="0.000005" iyz="0"
               izz="0.000005"/>
    </inertial>
  </link>

  <joint name="gripper_right3_to_gripper_right1" type="revolute">
    <axis xyz="0 0 1"/>
    <limit effort="1000.0" lower="-0.5" upper="0.5" velocity="2.0"/>
    <parent link="gripper_right3"/>
    <child link="gripper_right1"/>
    <origin xyz="0.027 0.016 0" rpy="0 0 0"/>
    <mimic joint="gripper_controller" multiplier="1.0" offset="0"/>
    <dynamics damping="0.5" friction="0.1"/>
  </joint>

  <!-- ===== ROS–Gazebo Control Plugin（完全保留原文件）===== -->
  <gazebo>
    <plugin name="gz_ros2_control::GazeboSimROS2ControlPlugin"
            filename="libgz_ros2_control-system.so">
      <parameters>MYCOBOT_CONFIG_PATH</parameters>
    </plugin>
  </gazebo>

  <!-- ===== ros2_control（原机械臂6轴 + 新增夹爪主动关节）===== -->
  <ros2_control name="MycobotSystem" type="system">
    <hardware>
      <plugin>gz_ros2_control/GazeboSimSystem</plugin>
      <param name="enable_joint_filtering">true</param>
    </hardware>

    <joint name="joint2_to_joint1">
      <command_interface name="position"/>
      <state_interface name="position"/>
      <state_interface name="velocity"/>
      <state_interface name="effort"/>
    </joint>
    <joint name="joint3_to_joint2">
      <command_interface name="position"/>
      <state_interface name="position"/>
      <state_interface name="velocity"/>
      <state_interface name="effort"/>
    </joint>
    <joint name="joint4_to_joint3">
      <command_interface name="position"/>
      <state_interface name="position"/>
      <state_interface name="velocity"/>
      <state_interface name="effort"/>
    </joint>
    <joint name="joint5_to_joint4">
      <command_interface name="position"/>
      <state_interface name="position"/>
      <state_interface name="velocity"/>
      <state_interface name="effort"/>
    </joint>
    <joint name="joint6_to_joint5">
      <command_interface name="position"/>
      <state_interface name="position"/>
      <state_interface name="velocity"/>
      <state_interface name="effort"/>
    </joint>
    <joint name="joint6output_to_joint6">
      <command_interface name="position"/>
      <state_interface name="position"/>
      <state_interface name="velocity"/>
      <state_interface name="effort"/>
    </joint>

    <!-- 夹爪主动关节（mimic 关节不在此处注册）-->
    <joint name="gripper_controller">
      <command_interface name="position">
        <param name="min">-0.74</param>
        <param name="max">0.15</param>
      </command_interface>
      <state_interface name="position"/>
      <state_interface name="velocity"/>
    </joint>

  </ros2_control>

</robot>